<!--
  Copyright 2016 The Cartographer Authors

  Licensed under the Apache License, Version 2.0 (the "License");
  you may not use this file except in compliance with the License.
  You may obtain a copy of the License at

       http://www.apache.org/licenses/LICENSE-2.0

  Unless required by applicable law or agreed to in writing, software
  distributed under the License is distributed on an "AS IS" BASIS,
  WITHOUT WARRANTIES OR CONDITIONS OF ANY KIND, either express or implied.
  See the License for the specific language governing permissions and
  limitations under the License.
-->

<?xml version="1.0"?>
<robot xmlns:xacro="http://www.ros.org/wiki/xacro" name="whill_cartographer_backpack_3d" >

    <link name="base_link">

    </link>

    <link name="base_floor">
        <visual>
            <geometry>
                <box size="0.600 0.400 0.050"/>
            </geometry>
            <material name="grey">
                <color rgba="0.5 0.5 0.5 1.0"/>
            </material>
        </visual>

        <collision>
            <geometry>
                <box size="0.600 0.400 0.050"/>
            </geometry>
        </collision>

        <inertial>
            <origin xyz="0 0 0" rpy="0 0 0" />
            <mass value="40" />
            <inertia ixx="1.0"  ixy="0.0"   ixz="0.0"
                                iyy="1.0"   iyz="0.0"
                                            izz="1.0" />
        </inertial>
    </link>

    <joint name="base_body_joint" type="fixed">
        <parent link="base_link" />
        <child link="base_floor" />
        <origin xyz="0.3 0 0.0" rpy="0 0 0"/>
    </joint>


    <link name="footrest_link">
        <collision>
            <geometry>
                <box size="0.250 0.260 0.050"/>
            </geometry>
        </collision>
        <visual>
            <geometry>
                <box size="0.250 0.260 0.050"/>
            </geometry>
            <material name="grey">
                <color rgba="0.5 0.5 0.5 1.0"/>
            </material>
        </visual>
        <inertial>
            <origin xyz="0 0 0" rpy="0 0 0" />
            <mass value="1" />
            <inertia ixx="1.0"  ixy="0.0"   ixz="0.0"
                                iyy="1.0"   iyz="0.0"
                                            izz="1.0" />
        </inertial>
    </link>

    <joint name="footrest_joint" type="fixed">
        <parent link="base_floor" />
        <child link="footrest_link" />
        <origin xyz="0.320 0 0" rpy="0 0 0"/>
    </joint>

    <link name="left_wheel_link">
        <visual>
            <geometry>
                <cylinder length="0.05" radius="0.1325"/>
            </geometry>
            <origin xyz="0 0 0" rpy="0 0 0" />
            <material name="black" />
        </visual>

        <collision>
            <geometry>
                <cylinder length="0.05" radius="0.1325"/>
            </geometry>
        </collision> 

        <inertial>
            <origin xyz="0 0 0"/>
            <mass value="0.500"/>
            <inertia ixx="0.0013541667" ixy="0" ixz="0" iyy="0.0013541667" iyz="0" izz="0.0025"/>
        </inertial>
    </link>


    <joint name="leftWheel" type="continuous">
        <parent link="base_floor" />
        <child link="left_wheel_link" />
        <origin xyz="-0.3 0.245 0" rpy="-1.57 0 0" />
        <axis xyz="0 0 1" />
    </joint>



    <link name="right_wheel_link">
        <collision>
            <origin xyz="0 0 0" rpy="0 0 0" />
            <geometry>
                <cylinder length="0.05" radius="0.1325"/>
            </geometry>
        </collision>
        <visual>
            <origin xyz="0 0 0" rpy="0 0 0" />
            <geometry>
                <cylinder length="0.05" radius="0.1325"/>
            </geometry>
            <material name="black" />
        </visual>
        <inertial>
            <origin xyz="0 0 0"/>
            <mass value="0.500"/>
            <inertia ixx="0.0013541667" ixy="0" ixz="0" iyy="0.0013541667" iyz="0" izz="0.0025"/>
        </inertial>
    </link>

    <joint name="rightWheel" type="continuous">
        <parent link="base_floor" />
        <child link="right_wheel_link" />
        <origin xyz="-0.3 -0.245 0" rpy="1.57 0 0" />
        <axis xyz="0 0 1" />
    </joint>


    <link name="frontwheel_left">
        <collision>
            <geometry>
                <cylinder length="0.05" radius="0.1325"/>
            </geometry>
        </collision>

        <visual>
            <geometry>
                <cylinder length="0.05" radius="0.1325"/>
            </geometry>
            <material name="black" />
        </visual>

        <inertial>
            <origin xyz="0 0 0" rpy="0 0 0" />
            <mass value="1.0" />
            <inertia ixx="1.0"  ixy="0.0"   ixz="0.0"
                                iyy="1.0"   iyz="0.0"
                                            izz="1.0" />
        </inertial>
    </link>
    
    <joint name="frontwheel_left_joint" type="fixed">
        <parent link="base_floor" />
        <child link="frontwheel_left" />
        <origin xyz="0.3 -0.245 0" rpy="1.57 0 0" />
        <axis xyz="0 0 1" />
    </joint>



    <link name="frontwheel_right">
        <collision>
            <geometry>
                <cylinder length="0.05" radius="0.1325"/>
            </geometry>
        </collision>

        <visual>
            <geometry>
                <cylinder length="0.05" radius="0.1325"/>
            </geometry>
            <material name="black" />
        </visual>

        <inertial>
            <origin xyz="0 0 0" rpy="0 0 0" />
            <mass value="1.0" />
            <inertia ixx="1.0"  ixy="0.0"   ixz="0.0"
                                iyy="1.0"   iyz="0.0"
                                            izz="1.0" />
        </inertial>    
    </link>

    <joint name="frontwheel_right_joint" type="fixed">
        <parent link="base_floor" />
        <child link="frontwheel_right"/>
        <origin xyz="0.3 0.245 0" rpy="1.57 0 0" />
        <axis xyz="0 0 -1" />
    </joint>

    <!-- IMU -->
    <link name="imu">
    </link>


    <joint name="imu_joint" type="fixed">
        <axis xyz="0 1 0" />
        <origin xyz="0.02 0 0.05" rpy="0 0.85521133347 3.14159265359"/>
        <parent link="base_link"/>
        <child link="imu"/>
    </joint>

  <link name="mrs_link">
    <visual>
      <origin xyz="0.0 0.0 0.0" />
      <geometry>
        <cylinder length="0.07" radius="0.05" />
      </geometry>
      <material name="gray" />
    </visual>
  </link>

  <joint name="mrs_link_joint" type="fixed">
    <parent link="base_link" />
    <child link="mrs_link" />
    <origin xyz="-0.1 0.0 1.2" rpy="0.0 0.087 0.0" />
  </joint>

    <!-- ===============  Transmission =============== -->

    <transmission name="right_wheel_trans">
        <type>transmission_interface/SimpleTransmission</type>
        <joint name="rightWheel">
            <hardwareInterface>hardware_interface/VelocityJointInterface</hardwareInterface>
        </joint>
        <actuator name="right_wheel_motor">
            <hardwareInterface>hardware_interface/VelocityJointInterface</hardwareInterface>
            <mechanicalReduction>30</mechanicalReduction>
        </actuator>
    </transmission>

    <transmission name="left_wheel_trans">
        <type>transmission_interface/SimpleTransmission</type>
        <joint name="leftWheel">
            <hardwareInterface>hardware_interface/VelocityJointInterface</hardwareInterface>
        </joint>
        <actuator name="left_wheel_motor">
            <hardwareInterface>hardware_interface/VelocityJointInterface</hardwareInterface>
            <mechanicalReduction>30</mechanicalReduction>
        </actuator>
    </transmission>
</robot>
